Workbook

Sheet Attrition Analysis
A1: Attrition & Tenure Cohort Dashboard
A2: All figures live-linked to EmployeeMaster. Cohorts: 0-3 / 3-6 / 6-12 / 12+ months.
A4: Total Headcount | C4: Active | E4: Resigned | G4: Attrition Rate | I4: Early Attrition (<3m) | K4: Avg Tenure (mths)
A5: =COUNTA(EmployeeMaster!$A$5:$A$224) | C5: =COUNTIF(EmployeeMaster!$H$5:$H$224,"Active") | E5: =COUNTIF(EmployeeMaster!$H$5:$H$224,"Resigned") | G5: =COUNTIF(EmployeeMaster!$H$5:$H$224,"Resigned")/COUNTA(EmployeeMaster!$A$5:$A$224) | I5: =COUNTIFS(EmployeeMaster!$H$5:$H$224,"Resigned",EmployeeMaster!$L$5:$L$224,"0-3 months")/COUNTIF(EmployeeMaster!$H$5:$H$224,"Resigned") | K5: =AVERAGE(EmployeeMaster!$K$5:$K$224)
A8: 1 | Headcount by Tenure Cohort | H8: 4 | Attrition by Department
A9: Tenure Cohort | B9: Headcount | C9: % of Total | D9: Active | E9: Resigned | F9: Attrition % (in cohort) | H9: Department | I9: Headcount | J9: Resigned | K9: Attrition %
A10: 0-3 months | B10: =COUNTIF(EmployeeMaster!$L$5:$L$224,A10) | C10: =B10/$B$4 | D10: =COUNTIFS(EmployeeMaster!$L$5:$L$224,A10,EmployeeMaster!$H$5:$H$224,"Active") | E10: =COUNTIFS(EmployeeMaster!$L$5:$L$224,A10,EmployeeMaster!$H$5:$H$224,"Resigned") | F10: =IFERROR(E10/B10,0) | H10: Operations | I10: =COUNTIF(EmployeeMaster!$D$5:$D$224,H10) | J10: =COUNTIFS(EmployeeMaster!$D$5:$D$224,H10,EmployeeMaster!$H$5:$H$224,"Resigned") | K10: =IFERROR(J10/I10,0)
A11: 3-6 months | B11: =COUNTIF(EmployeeMaster!$L$5:$L$224,A11) | C11: =B11/$B$4 | D11: =COUNTIFS(EmployeeMaster!$L$5:$L$224,A11,EmployeeMaster!$H$5:$H$224,"Active") | E11: =COUNTIFS(EmployeeMaster!$L$5:$L$224,A11,EmployeeMaster!$H$5:$H$224,"Resigned") | F11: =IFERROR(E11/B11,0) | H11: Customer Care | I11: =COUNTIF(EmployeeMaster!$D$5:$D$224,H11) | J11: =COUNTIFS(EmployeeMaster!$D$5:$D$224,H11,EmployeeMaster!$H$5:$H$224,"Resigned") | K11: =IFERROR(J11/I11,0)
A12: 6-12 months | B12: =COUNTIF(EmployeeMaster!$L$5:$L$224,A12) | C12: =B12/$B$4 | D12: =COUNTIFS(EmployeeMaster!$L$5:$L$224,A12,EmployeeMaster!$H$5:$H$224,"Active") | E12: =COUNTIFS(EmployeeMaster!$L$5:$L$224,A12,EmployeeMaster!$H$5:$H$224,"Resigned") | F12: =IFERROR(E12/B12,0) | H12: Sales | I12: =COUNTIF(EmployeeMaster!$D$5:$D$224,H12) | J12: =COUNTIFS(EmployeeMaster!$D$5:$D$224,H12,EmployeeMaster!$H$5:$H$224,"Resigned") | K12: =IFERROR(J12/I12,0)
A13: 12+ months | B13: =COUNTIF(EmployeeMaster!$L$5:$L$224,A13) | C13: =B13/$B$4 | D13: =COUNTIFS(EmployeeMaster!$L$5:$L$224,A13,EmployeeMaster!$H$5:$H$224,"Active") | E13: =COUNTIFS(EmployeeMaster!$L$5:$L$224,A13,EmployeeMaster!$H$5:$H$224,"Resigned") | F13: =IFERROR(E13/B13,0) | H13: IT Support | I13: =COUNTIF(EmployeeMaster!$D$5:$D$224,H13) | J13: =COUNTIFS(EmployeeMaster!$D$5:$D$224,H13,EmployeeMaster!$H$5:$H$224,"Resigned") | K13: =IFERROR(J13/I13,0)
A14: TOTAL | B14: =SUM(B10:B13) | C14: =SUM(C10:C13) | D14: =SUM(D10:D13) | E14: =SUM(E10:E13) | F14: =IFERROR(E14/B14,0) | H14: Admin | I14: =COUNTIF(EmployeeMaster!$D$5:$D$224,H14) | J14: =COUNTIFS(EmployeeMaster!$D$5:$D$224,H14,EmployeeMaster!$H$5:$H$224,"Resigned") | K14: =IFERROR(J14/I14,0)
H15: Quality | I15: =COUNTIF(EmployeeMaster!$D$5:$D$224,H15) | J15: =COUNTIFS(EmployeeMaster!$D$5:$D$224,H15,EmployeeMaster!$H$5:$H$224,"Resigned") | K15: =IFERROR(J15/I15,0)
A16: 2 | Gender × Tenure Cohort (headcount, and % female within cohort) | H16: Team Leaders | I16: =COUNTIF(EmployeeMaster!$D$5:$D$224,H16) | J16: =COUNTIFS(EmployeeMaster!$D$5:$D$224,H16,EmployeeMaster!$H$5:$H$224,"Resigned") | K16: =IFERROR(J16/I16,0)
A17: Tenure Cohort | B17: Female | C17: Male | D17: Total | E17: % Female | F17: % of Females Still Active | H17: Training | I17: =COUNTIF(EmployeeMaster!$D$5:$D$224,H17) | J17: =COUNTIFS(EmployeeMaster!$D$5:$D$224,H17,EmployeeMaster!$H$5:$H$224,"Resigned") | K17: =IFERROR(J17/I17,0)
A18: 0-3 months | B18: =COUNTIFS(EmployeeMaster!$L$5:$L$224,A18,EmployeeMaster!$C$5:$C$224,"Female") | C18: =COUNTIFS(EmployeeMaster!$L$5:$L$224,A18,EmployeeMaster!$C$5:$C$224,"Male") | D18: =B18+C18 | E18: =IFERROR(B18/D18,0) | F18: =IFERROR(COUNTIFS(EmployeeMaster!$L$5:$L$224,A18,EmployeeMaster!$C$5:$C$224,"Female",EmployeeMaster!$H$5:$H$224,"Active")/B18,0)
A19: 3-6 months | B19: =COUNTIFS(EmployeeMaster!$L$5:$L$224,A19,EmployeeMaster!$C$5:$C$224,"Female") | C19: =COUNTIFS(EmployeeMaster!$L$5:$L$224,A19,EmployeeMaster!$C$5:$C$224,"Male") | D19: =B19+C19 | E19: =IFERROR(B19/D19,0) | F19: =IFERROR(COUNTIFS(EmployeeMaster!$L$5:$L$224,A19,EmployeeMaster!$C$5:$C$224,"Female",EmployeeMaster!$H$5:$H$224,"Active")/B19,0)
A20: 6-12 months | B20: =COUNTIFS(EmployeeMaster!$L$5:$L$224,A20,EmployeeMaster!$C$5:$C$224,"Female") | C20: =COUNTIFS(EmployeeMaster!$L$5:$L$224,A20,EmployeeMaster!$C$5:$C$224,"Male") | D20: =B20+C20 | E20: =IFERROR(B20/D20,0) | F20: =IFERROR(COUNTIFS(EmployeeMaster!$L$5:$L$224,A20,EmployeeMaster!$C$5:$C$224,"Female",EmployeeMaster!$H$5:$H$224,"Active")/B20,0) | H20: 5 | Attrition by Campaign
A21: 12+ months | B21: =COUNTIFS(EmployeeMaster!$L$5:$L$224,A21,EmployeeMaster!$C$5:$C$224,"Female") | C21: =COUNTIFS(EmployeeMaster!$L$5:$L$224,A21,EmployeeMaster!$C$5:$C$224,"Male") | D21: =B21+C21 | E21: =IFERROR(B21/D21,0) | F21: =IFERROR(COUNTIFS(EmployeeMaster!$L$5:$L$224,A21,EmployeeMaster!$C$5:$C$224,"Female",EmployeeMaster!$H$5:$H$224,"Active")/B21,0) | H21: Campaign | I21: Headcount | J21: Resigned | K21: Attrition %
A22: TOTAL | B22: =SUM(B18:B21) | C22: =SUM(C18:C21) | D22: =SUM(D18:D21) | E22: =IFERROR(B22/D22,0) | F22: =IFERROR(COUNTIFS(EmployeeMaster!$C$5:$C$224,"Female",EmployeeMaster!$H$5:$H$224,"Active")/COUNTIF(EmployeeMaster!$C$5:$C$224,"Female"),0) | H22: Vodacom Upgrades | I22: =COUNTIF(EmployeeMaster!$E$5:$E$224,H22) | J22: =COUNTIFS(EmployeeMaster!$E$5:$E$224,H22,EmployeeMaster!$H$5:$H$224,"Resigned") | K22: =IFERROR(J22/I22,0)
H23: ABSA Collections | I23: =COUNTIF(EmployeeMaster!$E$5:$E$224,H23) | J23: =COUNTIFS(EmployeeMaster!$E$5:$E$224,H23,EmployeeMaster!$H$5:$H$224,"Resigned") | K23: =IFERROR(J23/I23,0)
A24: 3 | Gender Snapshot | H24: MTN Retentions | I24: =COUNTIF(EmployeeMaster!$E$5:$E$224,H24) | J24: =COUNTIFS(EmployeeMaster!$E$5:$E$224,H24,EmployeeMaster!$H$5:$H$224,"Resigned") | K24: =IFERROR(J24/I24,0)
A25: Total Females | B25: =COUNTIF(EmployeeMaster!$C$5:$C$224,"Female") | H25: Takealot Care | I25: =COUNTIF(EmployeeMaster!$E$5:$E$224,H25) | J25: =COUNTIFS(EmployeeMaster!$E$5:$E$224,H25,EmployeeMaster!$H$5:$H$224,"Resigned") | K25: =IFERROR(J25/I25,0)
A26: Females Still Active | B26: =COUNTIFS(EmployeeMaster!$C$5:$C$224,"Female",EmployeeMaster!$H$5:$H$224,"Active") | H26: Telkom Tech Support | I26: =COUNTIF(EmployeeMaster!$E$5:$E$224,H26) | J26: =COUNTIFS(EmployeeMaster!$E$5:$E$224,H26,EmployeeMaster!$H$5:$H$224,"Resigned") | K26: =IFERROR(J26/I26,0)
A27: % of Workforce Female | B27: =COUNTIF(EmployeeMaster!$C$5:$C$224,"Female")/COUNTA(EmployeeMaster!$A$5:$A$224) | H27: Nedbank Debt Review | I27: =COUNTIF(EmployeeMaster!$E$5:$E$224,H27) | J27: =COUNTIFS(EmployeeMaster!$E$5:$E$224,H27,EmployeeMaster!$H$5:$H$224,"Resigned") | K27: =IFERROR(J27/I27,0)
A28: % of Females Still Employed | B28: =COUNTIFS(EmployeeMaster!$C$5:$C$224,"Female",EmployeeMaster!$H$5:$H$224,"Active")/COUNTIF(EmployeeMaster!$C$5:$C$224,"Female") | H28: DStv Upsell | I28: =COUNTIF(EmployeeMaster!$E$5:$E$224,H28) | J28: =COUNTIFS(EmployeeMaster!$E$5:$E$224,H28,EmployeeMaster!$H$5:$H$224,"Resigned") | K28: =IFERROR(J28/I28,0)
A29: Female Attrition Rate | B29: =COUNTIFS(EmployeeMaster!$C$5:$C$224,"Female",EmployeeMaster!$H$5:$H$224,"Resigned")/COUNTIF(EmployeeMaster!$C$5:$C$224,"Female") | H29: Discovery Lead Gen | I29: =COUNTIF(EmployeeMaster!$E$5:$E$224,H29) | J29: =COUNTIFS(EmployeeMaster!$E$5:$E$224,H29,EmployeeMaster!$H$5:$H$224,"Resigned") | K29: =IFERROR(J29/I29,0)
A30: Male Attrition Rate | B30: =COUNTIFS(EmployeeMaster!$C$5:$C$224,"Male",EmployeeMaster!$H$5:$H$224,"Resigned")/COUNTIF(EmployeeMaster!$C$5:$C$224,"Male") | H30: Cell C Winback | I30: =COUNTIF(EmployeeMaster!$E$5:$E$224,H30) | J30: =COUNTIFS(EmployeeMaster!$E$5:$E$224,H30,EmployeeMaster!$H$5:$H$224,"Resigned") | K30: =IFERROR(J30/I30,0)
H31: OUTsurance Sales | I31: =COUNTIF(EmployeeMaster!$E$5:$E$224,H31) | J31: =COUNTIFS(EmployeeMaster!$E$5:$E$224,H31,EmployeeMaster!$H$5:$H$224,"Resigned") | K31: =IFERROR(J31/I31,0)
A32: 6 | Monthly Resignation Trend (2026) | H32: Standard Bank Helpdesk | I32: =COUNTIF(EmployeeMaster!$E$5:$E$224,H32) | J32: =COUNTIFS(EmployeeMaster!$E$5:$E$224,H32,EmployeeMaster!$H$5:$H$224,"Resigned") | K32: =IFERROR(J32/I32,0)
A33: Month | B33: Resignations | H33: Shoprite Surveys | I33: =COUNTIF(EmployeeMaster!$E$5:$E$224,H33) | J33: =COUNTIFS(EmployeeMaster!$E$5:$E$224,H33,EmployeeMaster!$H$5:$H$224,"Resigned") | K33: =IFERROR(J33/I33,0)
A34: Jan | B34: =COUNTIFS(EmployeeMaster!$I$5:$I$224,">="&DATE(2026,1,1),EmployeeMaster!$I$5:$I$224,"<"&DATE(2026,2,1))
A35: Feb | B35: =COUNTIFS(EmployeeMaster!$I$5:$I$224,">="&DATE(2026,2,1),EmployeeMaster!$I$5:$I$224,"<"&DATE(2026,3,1))
A36: Mar | B36: =COUNTIFS(EmployeeMaster!$I$5:$I$224,">="&DATE(2026,3,1),EmployeeMaster!$I$5:$I$224,"<"&DATE(2026,4,1))
A37: Apr | B37: =COUNTIFS(EmployeeMaster!$I$5:$I$224,">="&DATE(2026,4,1),EmployeeMaster!$I$5:$I$224,"<"&DATE(2026,5,1))
A38: May | B38: =COUNTIFS(EmployeeMaster!$I$5:$I$224,">="&DATE(2026,5,1),EmployeeMaster!$I$5:$I$224,"<"&DATE(2026,6,1))
A39: Jun | B39: =COUNTIFS(EmployeeMaster!$I$5:$I$224,">="&DATE(2026,6,1),EmployeeMaster!$I$5:$I$224,"<"&DATE(2026,7,1))
A40: Jul | B40: =COUNTIFS(EmployeeMaster!$I$5:$I$224,">="&DATE(2026,7,1),EmployeeMaster!$I$5:$I$224,"<"&DATE(2026,8,1))

Sheet EmployeeMaster
A1: Employee Master — 220 Staff Across Campaigns
A2: Source for cohort attrition. Tenure & cohort columns are live formulas (recalc on open).
A4: Emp ID | B4: Employee | C4: Gender | D4: Department | E4: Campaign | F4: Location | G4: Hire Date | H4: Status | I4: Exit Date | J4: Age | K4: Tenure (mths) | L4: Tenure Cohort | M4: Monthly Salary
A5: E3001 | B5: Zodwa Nkosi | C5: Male | D5: Training | E5: DStv Upsell | F5: Pretoria | G5: 45227 | H5: Active | J5: 47 | K5: =IF(H5="Resigned",(I5-G5),(TODAY()-G5))/30.437 | L5: =IF(K5<3,"0-3 months",IF(K5<6,"3-6 months",IF(K5<12,"6-12 months","12+ months"))) | M5: 33000
A6: E3002 | B6: Keabetswe Fourie | C6: Female | D6: Quality | E6: Takealot Care | F6: Port Elizabeth | G6: 45930 | H6: Active | J6: 31 | K6: =IF(H6="Resigned",(I6-G6),(TODAY()-G6))/30.437 | L6: =IF(K6<3,"0-3 months",IF(K6<6,"3-6 months",IF(K6<12,"6-12 months","12+ months"))) | M6: 28000
A7: E3003 | B7: Ntombizodwa Govender | C7: Female | D7: Sales | E7: DStv Upsell | F7: Johannesburg | G7: 45737 | H7: Active | J7: 52 | K7: =IF(H7="Resigned",(I7-G7),(TODAY()-G7))/30.437 | L7: =IF(K7<3,"0-3 months",IF(K7<6,"3-6 months",IF(K7<12,"6-12 months","12+ months"))) | M7: 18500
A8: E3004 | B8: Sipho Meyer | C8: Male | D8: Training | E8: Discovery Lead Gen | F8: Cape Town | G8: 45225 | H8: Active | J8: 25 | K8: =IF(H8="Resigned",(I8-G8),(TODAY()-G8))/30.437 | L8: =IF(K8<3,"0-3 months",IF(K8<6,"3-6 months",IF(K8<12,"6-12 months","12+ months"))) | M8: 13500
A9: E3005 | B9: Andile Khumalo | C9: Female | D9: Operations | E9: MTN Retentions | F9: Cape Town | G9: 45949 | H9: Resigned | I9: 46075 | J9: 46 | K9: =IF(H9="Resigned",(I9-G9),(TODAY()-G9))/30.437 | L9: =IF(K9<3,"0-3 months",IF(K9<6,"3-6 months",IF(K9<12,"6-12 months","12+ months"))) | M9: 18500
A10: E3006 | B10: Nokuthula Petersen | C10: Female | D10: Quality | E10: Takealot Care | F10: Cape Town | G10: 45882 | H10: Active | J10: 41 | K10: =IF(H10="Resigned",(I10-G10),(TODAY()-G10))/30.437 | L10: =IF(K10<3,"0-3 months",IF(K10<6,"3-6 months",IF(K10<12,"6-12 months","12+ months"))) | M10: 13500
A11: E3007 | B11: Andile Tshabalala | C11: Male | D11: Team Leaders | E11: DStv Upsell | F11: Cape Town | G11: 45684 | H11: Active | J11: 34 | K11: =IF(H11="Resigned",(I11-G11),(TODAY()-G11))/30.437 | L11: =IF(K11<3,"0-3 months",IF(K11<6,"3-6 months",IF(K11<12,"6-12 months","12+ months"))) | M11: 39000
A12: E3008 | B12: Thabo Dlamini | C12: Male | D12: Quality | E12: ABSA Collections | F12: Port Elizabeth | G12: 44965 | H12: Active | J12: 43 | K12: =IF(H12="Resigned",(I12-G12),(TODAY()-G12))/30.437 | L12: =IF(K12<3,"0-3 months",IF(K12<6,"3-6 months",IF(K12<12,"6-12 months","12+ months"))) | M12: 24000
A13: E3009 | B13: Ntombizodwa Zulu | C13: Female | D13: Sales | E13: Telkom Tech Support | F13: Cape Town | G13: 45244 | H13: Active | J13: 54 | K13: =IF(H13="Resigned",(I13-G13),(TODAY()-G13))/30.437 | L13: =IF(K13<3,"0-3 months",IF(K13<6,"3-6 months",IF(K13<12,"6-12 months","12+ months"))) | M13: 16500
A14: E3010 | B14: Refilwe Radebe | C14: Male | D14: Training | E14: MTN Retentions | F14: Pretoria | G14: 45761 | H14: Active | J14: 48 | K14: =IF(H14="Resigned",(I14-G14),(TODAY()-G14))/30.437 | L14: =IF(K14<3,"0-3 months",IF(K14<6,"3-6 months",IF(K14<12,"6-12 months","12+ months"))) | M14: 16500
A15: E3011 | B15: Thabo Nel | C15: Female | D15: Customer Care | E15: Takealot Care | F15: Johannesburg | G15: 45639 | H15: Active | J15: 24 | K15: =IF(H15="Resigned",(I15-G15),(TODAY()-G15))/30.437 | L15: =IF(K15<3,"0-3 months",IF(K15<6,"3-6 months",IF(K15<12,"6-12 months","12+ months"))) | M15: 33000
A16: E3012 | B16: Zanele Sithole | C16: Female | D16: Quality | E16: Takealot Care | F16: Pretoria | G16: 45682 | H16: Active | J16: 48 | K16: =IF(H16="Resigned",(I16-G16),(TODAY()-G16))/30.437 | L16: =IF(K16<3,"0-3 months",IF(K16<6,"3-6 months",IF(K16<12,"6-12 months","12+ months"))) | M16: 13500
A17: E3013 | B17: Sibusiso Fourie | C17: Male | D17: Admin | E17: DStv Upsell | F17: Pretoria | G17: 45705 | H17: Active | J17: 30 | K17: =IF(H17="Resigned",(I17-G17),(TODAY()-G17))/30.437 | L17: =IF(K17<3,"0-3 months",IF(K17<6,"3-6 months",IF(K17<12,"6-12 months","12+ months"))) | M17: 15000
A18: E3014 | B18: Lindiwe Mokoena | C18: Female | D18: Training | E18: OUTsurance Sales | F18: Johannesburg | G18: 45367 | H18: Resigned | I18: 45819 | J18: 22 | K18: =IF(H18="Resigned",(I18-G18),(TODAY()-G18))/30.437 | L18: =IF(K18<3,"0-3 months",IF(K18<6,"3-6 months",IF(K18<12,"6-12 months","12+ months"))) | M18: 24000
A19: E3015 | B19: Boitumelo Zulu | C19: Female | D19: Team Leaders | E19: DStv Upsell | F19: Cape Town | G19: 45640 | H19: Active | J19: 34 | K19: =IF(H19="Resigned",(I19-G19),(TODAY()-G19))/30.437 | L19: =IF(K19<3,"0-3 months",IF(K19<6,"3-6 months",IF(K19<12,"6-12 months","12+ months"))) | M19: 18500
A20: E3016 | B20: Katlego Jacobs | C20: Female | D20: Training | E20: Discovery Lead Gen | F20: Cape Town | G20: 45810 | H20: Active | J20: 38 | K20: =IF(H20="Resigned",(I20-G20),(TODAY()-G20))/30.437 | L20: =IF(K20<3,"0-3 months",IF(K20<6,"3-6 months",IF(K20<12,"6-12 months","12+ months"))) | M20: 33000
A21: E3017 | B21: Sibusiso Radebe | C21: Female | D21: Customer Care | E21: OUTsurance Sales | F21: Port Elizabeth | G21: 45488 | H21: Active | J21: 45 | K21: =IF(H21="Resigned",(I21-G21),(TODAY()-G21))/30.437 | L21: =IF(K21<3,"0-3 months",IF(K21<6,"3-6 months",IF(K21<12,"6-12 months","12+ months"))) | M21: 33000
A22: E3018 | B22: Onalenna Naidoo | C22: Female | D22: IT Support | E22: Discovery Lead Gen | F22: Port Elizabeth | G22: 45848 | H22: Active | J22: 32 | K22: =IF(H22="Resigned",(I22-G22),(TODAY()-G22))/30.437 | L22: =IF(K22<3,"0-3 months",IF(K22<6,"3-6 months",IF(K22<12,"6-12 months","12+ months"))) | M22: 18500
A23: E3019 | B23: Mpho Zulu | C23: Female | D23: Quality | E23: Standard Bank Helpdesk | F23: Cape Town | G23: 45915 | H23: Active | J23: 29 | K23: =IF(H23="Resigned",(I23-G23),(TODAY()-G23))/30.437 | L23: =IF(K23<3,"0-3 months",IF(K23<6,"3-6 months",IF(K23<12,"6-12 months","12+ months"))) | M23: 33000
A24: E3020 | B24: Precious Sithole | C24: Female | D24: Operations | E24: Shoprite Surveys | F24: Cape Town | G24: 45844 | H24: Active | J24: 28 | K24: =IF(H24="Resigned",(I24-G24),(TODAY()-G24))/30.437 | L24: =IF(K24<3,"0-3 months",IF(K24<6,"3-6 months",IF(K24<12,"6-12 months","12+ months"))) | M24: 28000
A25: E3021 | B25: Musa Khumalo | C25: Female | D25: Operations | E25: Telkom Tech Support | F25: Port Elizabeth | G25: 45245 | H25: Active | J25: 23 | K25: =IF(H25="Resigned",(I25-G25),(TODAY()-G25))/30.437 | L25: =IF(K25<3,"0-3 months",IF(K25<6,"3-6 months",IF(K25<12,"6-12 months","12+ months"))) | M25: 28000
A26: E3022 | B26: Themba Mabaso | C26: Female | D26: Training | E26: Nedbank Debt Review | F26: Port Elizabeth | G26: 45027 | H26: Active | J26: 46 | K26: =IF(H26="Resigned",(I26-G26),(TODAY()-G26))/30.437 | L26: =IF(K26<3,"0-3 months",IF(K26<6,"3-6 months",IF(K26<12,"6-12 months","12+ months"))) | M26: 24000
A27: E3023 | B27: Lindiwe Tshabalala | C27: Female | D27: IT Support | E27: Telkom Tech Support | F27: Durban | G27: 45348 | H27: Active | J27: 47 | K27: =IF(H27="Resigned",(I27-G27),(TODAY()-G27))/30.437 | L27: =IF(K27<3,"0-3 months",IF(K27<6,"3-6 months",IF(K27<12,"6-12 months","12+ months"))) | M27: 18500
A28: E3024 | B28: Lindiwe Meyer | C28: Female | D28: Operations | E28: Standard Bank Helpdesk | F28: Cape Town | G28: 45686 | H28: Active | J28: 53 | K28: =IF(H28="Resigned",(I28-G28),(TODAY()-G28))/30.437 | L28: =IF(K28<3,"0-3 months",IF(K28<6,"3-6 months",IF(K28<12,"6-12 months","12+ months"))) | M28: 13500
A29: E3025 | B29: Vusi Ndlovu | C29: Female | D29: IT Support | E29: ABSA Collections | F29: Durban | G29: 45680 | H29: Active | J29: 38 | K29: =IF(H29="Resigned",(I29-G29),(TODAY()-G29))/30.437 | L29: =IF(K29<3,"0-3 months",IF(K29<6,"3-6 months",IF(K29<12,"6-12 months","12+ months"))) | M29: 18500
A30: E3026 | B30: Tebogo Mthembu | C30: Female | D30: Admin | E30: MTN Retentions | F30: Durban | G30: 45359 | H30: Active | J30: 46 | K30: =IF(H30="Resigned",(I30-G30),(TODAY()-G30))/30.437 | L30: =IF(K30<3,"0-3 months",IF(K30<6,"3-6 months",IF(K30<12,"6-12 months","12+ months"))) | M30: 28000
... A34: E3030 | B34: Siyabonga Ngcobo | C34: Female | D34: Quality | E34: Cell C Winback | F34: Cape Town | G34: 45763 | H34: Active | J34: 31 | K34: =IF(H34="Resigned",(I34-G34),(TODAY()-G34))/30.437 | L34: =IF(K34<3,"0-3 months",IF(K34<6,"3-6 months",IF(K34<12,"6-12 months","12+ months"))) | M34: 24000
A35: E3031 | B35: Nomvula Naidoo | C35: Male | D35: Training | E35: Vodacom Upgrades | F35: Cape Town | G35: 45700 | H35: Resigned | I35: 46169 | J35: 50 | K35: =IF(H35="Resigned",(I35-G35),(TODAY()-G35))/30.437 | L35: =IF(K35<3,"0-3 months",IF(K35<6,"3-6 months",IF(K35<12,"6-12 months","12+ months"))) | M35: 39000
A36: E3032 | B36: Nonhlanhla Khumalo | C36: Male | D36: Admin | E36: Standard Bank Helpdesk | F36: Johannesburg | G36: 45826 | H36: Active | J36: 40 | K36: =IF(H36="Resigned",(I36-G36),(TODAY()-G36))/30.437 | L36: =IF(K36<3,"0-3 months",IF(K36<6,"3-6 months",IF(K36<12,"6-12 months","12+ months"))) | M36: 24000
A37: E3033 | B37: Naledi Buthelezi | C37: Male | D37: IT Support | E37: Nedbank Debt Review | F37: Port Elizabeth | G37: 45715 | H37: Resigned | I37: 46206 | J37: 52 | K37: =IF(H37="Resigned",(I37-G37),(TODAY()-G37))/30.437 | L37: =IF(K37<3,"0-3 months",IF(K37<6,"3-6 months",IF(K37<12,"6-12 months","12+ months"))) | M37: 28000
A38: E3034 | B38: Bongani Mthembu | C38: Male | D38: Training | E38: MTN Retentions | F38: Durban | G38: 45574 | H38: Active | J38: 27 | K38: =IF(H38="Resigned",(I38-G38),(TODAY()-G38))/30.437 | L38: =IF(K38<3,"0-3 months",IF(K38<6,"3-6 months",IF(K38<12,"6-12 months","12+ months"))) | M38: 39000
A39: E3035 | B39: Wandile Dlamini | C39: Male | D39: Quality | E39: Vodacom Upgrades | F39: Durban | G39: 45601 | H39: Active | J39: 30 | K39: =IF(H39="Resigned",(I39-G39),(TODAY()-G39))/30.437 | L39: =IF(K39<3,"0-3 months",IF(K39<6,"3-6 months",IF(K39<12,"6-12 months","12+ months"))) | M39: 16500
A40: E3036 | B40: Mandla Mokoena | C40: Female | D40: Customer Care | E40: ABSA Collections | F40: Johannesburg | G40: 45250 | H40: Active | J40: 23 | K40: =IF(H40="Resigned",(I40-G40),(TODAY()-G40))/30.437 | L40: =IF(K40<3,"0-3 months",IF(K40<6,"3-6 months",IF(K40<12,"6-12 months","12+ months"))) | M40: 39000
A41: E3037 | B41: Siyabonga Sithole | C41: Female | D41: Team Leaders | E41: Shoprite Surveys | F41: Port Elizabeth | G41: 44892 | H41: Active | J41: 23 | K41: =IF(H41="Resigned",(I41-G41),(TODAY()-G41))/30.437 | L41: =IF(K41<3,"0-3 months",IF(K41<6,"3-6 months",IF(K41<12,"6-12 months","12+ months"))) | M41: 28000
A42: E3038 | B42: Tshepo Ndlovu | C42: Male | D42: Admin | E42: Vodacom Upgrades | F42: Pretoria | G42: 46147 | H42: Active | J42: 34 | K42: =IF(H42="Resigned",(I42-G42),(TODAY()-G42))/30.437 | L42: =IF(K42<3,"0-3 months",IF(K42<6,"3-6 months",IF(K42<12,"6-12 months","12+ months"))) | M42: 15000
A43: E3039 | B43: Kabelo Nkosi | C43: Male | D43: Sales | E43: Vodacom Upgrades | F43: Durban | G43: 45694 | H43: Active | J43: 44 | K43: =IF(H43="Resigned",(I43-G43),(TODAY()-G43))/30.437 | L43: =IF(K43<3,"0-3 months",IF(K43<6,"3-6 months",IF(K43<12,"6-12 months","12+ months"))) | M43: 39000
A44: E3040 | B44: Boitumelo Van Wyk | C44: Male | D44: IT Support | E44: OUTsurance Sales | F44: Johannesburg | G44: 45838 | H44: Active | J44: 27 | K44: =IF(H44="Resigned",(I44-G44),(TODAY()-G44))/30.437 | L44: =IF(K44<3,"0-3 months",IF(K44<6,"3-6 months",IF(K44<12,"6-12 months","12+ months"))) | M44: 21000
...
