Workbook

Sheet Dashboard
A1: Capacity Planning Dashboard
A2: Aggregated from the WFM Model tab
A4: Total Forecast Contacts | C4: Total Required FTE | E4: Total Scheduled FTE | G4: Net Variance (FTE) | I4: Avg Shrinkage | K4: Understaffed Slots
A5: =SUM('WFM Model'!C8:C55) -> 194723 | C5: =SUM('WFM Model'!G8:G55) -> 655.4731 | E5: =SUM('WFM Model'!H8:H55) -> 653 | G5: =SUM('WFM Model'!I8:I55) -> -2.4730951 | I5: =AVERAGE('WFM Model'!E8:E55) -> 0.31527083 | K5: =COUNTIF('WFM Model'!K8:K55,"Understaffed") -> 15
A8: Campaign | B8: Required FTE | C8: Scheduled FTE | D8: Variance | E8: Avg Coverage
A9: Vodacom Upgrades | B9: =SUMIF('WFM Model'!$A$8:$A$55,A9,'WFM Model'!$G$8:$G$55) -> 35.711931 | C9: =SUMIF('WFM Model'!$A$8:$A$55,A9,'WFM Model'!$H$8:$H$55) -> 38 | D9: =C9-B9 -> 2.2880694 | E9: =C9/B9 -> 1.0640702
A10: ABSA Collections | B10: =SUMIF('WFM Model'!$A$8:$A$55,A10,'WFM Model'!$G$8:$G$55) -> 31.997154 | C10: =SUMIF('WFM Model'!$A$8:$A$55,A10,'WFM Model'!$H$8:$H$55) -> 31 | D10: =C10-B10 -> -0.9971537 | E10: =C10/B10 -> 0.96883617
A11: MTN Retentions | B11: =SUMIF('WFM Model'!$A$8:$A$55,A11,'WFM Model'!$G$8:$G$55) -> 110.86138 | C11: =SUMIF('WFM Model'!$A$8:$A$55,A11,'WFM Model'!$H$8:$H$55) -> 115 | D11: =C11-B11 -> 4.1386209 | E11: =C11/B11 -> 1.0373315
A12: Takealot Care | B12: =SUMIF('WFM Model'!$A$8:$A$55,A12,'WFM Model'!$G$8:$G$55) -> 46.550525 | C12: =SUMIF('WFM Model'!$A$8:$A$55,A12,'WFM Model'!$H$8:$H$55) -> 46 | D12: =C12-B12 -> -0.55052472 | E12: =C12/B12 -> 0.98817361
A13: Telkom Tech Support | B13: =SUMIF('WFM Model'!$A$8:$A$55,A13,'WFM Model'!$G$8:$G$55) -> 44.876913 | C13: =SUMIF('WFM Model'!$A$8:$A$55,A13,'WFM Model'!$H$8:$H$55) -> 45 | D13: =C13-B13 -> 0.12308657 | E13: =C13/B13 -> 1.0027428
A14: Nedbank Debt Review | B14: =SUMIF('WFM Model'!$A$8:$A$55,A14,'WFM Model'!$G$8:$G$55) -> 58.038537 | C14: =SUMIF('WFM Model'!$A$8:$A$55,A14,'WFM Model'!$H$8:$H$55) -> 57 | D14: =C14-B14 -> -1.0385368 | E14: =C14/B14 -> 0.98210608
A15: DStv Upsell | B15: =SUMIF('WFM Model'!$A$8:$A$55,A15,'WFM Model'!$G$8:$G$55) -> 42.655962 | C15: =SUMIF('WFM Model'!$A$8:$A$55,A15,'WFM Model'!$H$8:$H$55) -> 43 | D15: =C15-B15 -> 0.34403848 | E15: =C15/B15 -> 1.0080654
A16: Discovery Lead Gen | B16: =SUMIF('WFM Model'!$A$8:$A$55,A16,'WFM Model'!$G$8:$G$55) -> 52.721569 | C16: =SUMIF('WFM Model'!$A$8:$A$55,A16,'WFM Model'!$H$8:$H$55) -> 52 | D16: =C16-B16 -> -0.72156857 | E16: =C16/B16 -> 0.9863136
A17: Cell C Winback | B17: =SUMIF('WFM Model'!$A$8:$A$55,A17,'WFM Model'!$G$8:$G$55) -> 49.761672 | C17: =SUMIF('WFM Model'!$A$8:$A$55,A17,'WFM Model'!$H$8:$H$55) -> 48 | D17: =C17-B17 -> -1.7616718 | E17: =C17/B17 -> 0.96459782
A18: OUTsurance Sales | B18: =SUMIF('WFM Model'!$A$8:$A$55,A18,'WFM Model'!$G$8:$G$55) -> 39.735581 | C18: =SUMIF('WFM Model'!$A$8:$A$55,A18,'WFM Model'!$H$8:$H$55) -> 38 | D18: =C18-B18 -> -1.7355811 | E18: =C18/B18 -> 0.95632174
A19: Standard Bank Helpdesk | B19: =SUMIF('WFM Model'!$A$8:$A$55,A19,'WFM Model'!$G$8:$G$55) -> 64.400022 | C19: =SUMIF('WFM Model'!$A$8:$A$55,A19,'WFM Model'!$H$8:$H$55) -> 60 | D19: =C19-B19 -> -4.4000218 | E19: =C19/B19 -> 0.9316767
A20: Shoprite Surveys | B20: =SUMIF('WFM Model'!$A$8:$A$55,A20,'WFM Model'!$G$8:$G$55) -> 78.161852 | C20: =SUMIF('WFM Model'!$A$8:$A$55,A20,'WFM Model'!$H$8:$H$55) -> 80 | D20: =C20-B20 -> 1.8381481 | E20: =C20/B20 -> 1.0235172

Sheet WFM Model
A1: Workforce Capacity & Shrinkage Model — Required vs Scheduled FTE
A2: Erlang-style staffing: contacts × AHT → productive hours → Required FTE (net of shrinkage & occupancy)
A4: Paid hours / FTE / week | D4: 40
A5: Target occupancy | D5: 0.85
A7: Campaign | B7: Week | C7: Forecast Contacts | D7: AHT (sec) | E7: Shrinkage % | F7: Req. Prod. Hours | G7: Required FTE | H7: Scheduled FTE | I7: Variance | J7: Coverage % | K7: Service Risk
A8: Vodacom Upgrades | B8: Wk 27 | C8: 2650 | D8: 259 | E8: 0.253 | F8: =C8*D8/3600 -> 190.65278 | G8: =F8/($D$4*(1-E8)*$D$5) -> 7.5066059 | H8: =ROUND(G8*1.007,0) -> 8 | I8: =H8-G8 -> 0.49339406 | J8: =H8/G8 -> 1.065728 | K8: =IF(J8<0.95,"Understaffed",IF(J8>1.15,"Overstaffed","Balanced")) -> Balanced
A9: Vodacom Upgrades | B9: Wk 28 | C9: 3435 | D9: 276 | E9: 0.319 | F9: =C9*D9/3600 -> 263.35 | G9: =F9/($D$4*(1-E9)*$D$5) -> 11.373845 | H9: =ROUND(G9*1.116,0) -> 13 | I9: =H9-G9 -> 1.6261553 | J9: =H9/G9 -> 1.1429732 | K9: =IF(J9<0.95,"Understaffed",IF(J9>1.15,"Overstaffed","Balanced")) -> Balanced
A10: Vodacom Upgrades | B10: Wk 29 | C10: 2481 | D10: 314 | E10: 0.306 | F10: =C10*D10/3600 -> 216.39833 | G10: =F10/($D$4*(1-E10)*$D$5) -> 9.1709753 | H10: =ROUND(G10*1.012,0) -> 9 | I10: =H10-G10 -> -0.17097531 | J10: =H10/G10 -> 0.98135691 | K10: =IF(J10<0.95,"Understaffed",IF(J10>1.15,"Overstaffed","Balanced")) -> Balanced
A11: Vodacom Upgrades | B11: Wk 30 | C11: 2339 | D11: 275 | E11: 0.314 | F11: =C11*D11/3600 -> 178.67361 | G11: =F11/($D$4*(1-E11)*$D$5) -> 7.6605047 | H11: =ROUND(G11*1.061,0) -> 8 | I11: =H11-G11 -> 0.33949532 | J11: =H11/G11 -> 1.0443176 | K11: =IF(J11<0.95,"Understaffed",IF(J11>1.15,"Overstaffed","Balanced")) -> Balanced
A12: ABSA Collections | B12: Wk 27 | C12: 3379 | D12: 241 | E12: 0.337 | F12: =C12*D12/3600 -> 226.20528 | G12: =F12/($D$4*(1-E12)*$D$5) -> 10.034836 | H12: =ROUND(G12*0.896,0) -> 9 | I12: =H12-G12 -> -1.0348362 | J12: =H12/G12 -> 0.89687563 | K12: =IF(J12<0.95,"Understaffed",IF(J12>1.15,"Overstaffed","Balanced")) -> Understaffed
A13: ABSA Collections | B13: Wk 28 | C13: 2756 | D13: 211 | E13: 0.355 | F13: =C13*D13/3600 -> 161.53222 | G13: =F13/($D$4*(1-E13)*$D$5) -> 7.3658104 | H13: =ROUND(G13*1.035,0) -> 8 | I13: =H13-G13 -> 0.63418959 | J13: =H13/G13 -> 1.0860991 | K13: =IF(J13<0.95,"Understaffed",IF(J13>1.15,"Overstaffed","Balanced")) -> Balanced
A14: ABSA Collections | B14: Wk 29 | C14: 2736 | D14: 219 | E14: 0.272 | F14: =C14*D14/3600 -> 166.44 | G14: =F14/($D$4*(1-E14)*$D$5) -> 6.7243051 | H14: =ROUND(G14*0.948,0) -> 6 | I14: =H14-G14 -> -0.72430511 | J14: =H14/G14 -> 0.89228551 | K14: =IF(J14<0.95,"Understaffed",IF(J14>1.15,"Overstaffed","Balanced")) -> Understaffed
A15: ABSA Collections | B15: Wk 30 | C15: 2484 | D15: 263 | E15: 0.322 | F15: =C15*D15/3600 -> 181.47 | G15: =F15/($D$4*(1-E15)*$D$5) -> 7.872202 | H15: =ROUND(G15*1.067,0) -> 8 | I15: =H15-G15 -> 0.12779802 | J15: =H15/G15 -> 1.0162341 | K15: =IF(J15<0.95,"Understaffed",IF(J15>1.15,"Overstaffed","Balanced")) -> Balanced
A16: MTN Retentions | B16: Wk 27 | C16: 8158 | D16: 344 | E16: 0.331 | F16: =C16*D16/3600 -> 779.54222 | G16: =F16/($D$4*(1-E16)*$D$5) -> 34.271618 | H16: =ROUND(G16*0.925,0) -> 32 | I16: =H16-G16 -> -2.271618 | J16: =H16/G16 -> 0.93371722 | K16: =IF(J16<0.95,"Understaffed",IF(J16>1.15,"Overstaffed","Balanced")) -> Understaffed
A17: MTN Retentions | B17: Wk 28 | C17: 8159 | D17: 215 | E17: 0.364 | F17: =C17*D17/3600 -> 487.27361 | G17: =F17/($D$4*(1-E17)*$D$5) -> 22.533926 | H17: =ROUND(G17*1.088,0) -> 25 | I17: =H17-G17 -> 2.4660742 | J17: =H17/G17 -> 1.1094383 | K17: =IF(J17<0.95,"Understaffed",IF(J17>1.15,"Overstaffed","Balanced")) -> Balanced
A18: MTN Retentions | B18: Wk 29 | C18: 8212 | D18: 242 | E18: 0.35 | F18: =C18*D18/3600 -> 552.02889 | G18: =F18/($D$4*(1-E18)*$D$5) -> 24.978683 | H18: =ROUND(G18*1.049,0) -> 26 | I18: =H18-G18 -> 1.0213172 | J18: =H18/G18 -> 1.0408876 | K18: =IF(J18<0.95,"Understaffed",IF(J18>1.15,"Overstaffed","Balanced")) -> Balanced
A19: MTN Retentions | B19: Wk 30 | C19: 7796 | D19: 336 | E19: 0.264 | F19: =C19*D19/3600 -> 727.62667 | G19: =F19/($D$4*(1-E19)*$D$5) -> 29.077153 | H19: =ROUND(G19*1.114,0) -> 32 | I19: =H19-G19 -> 2.9228474 | J19: =H19/G19 -> 1.1005204 | K19: =IF(J19<0.95,"Understaffed",IF(J19>1.15,"Overstaffed","Balanced")) -> Balanced
A20: Takealot Care | B20: Wk 27 | C20: 3301 | D20: 254 | E20: 0.308 | F20: =C20*D20/3600 -> 232.90389 | G20: =F20/($D$4*(1-E20)*$D$5) -> 9.8990092 | H20: =ROUND(G20*0.907,0) -> 9 | I20: =H20-G20 -> -0.89900922 | J20: =H20/G20 -> 0.9091819 | K20: =IF(J20<0.95,"Understaffed",IF(J20>1.15,"Overstaffed","Balanced")) -> Understaffed
A21: Takealot Care | B21: Wk 28 | C21: 3818 | D21: 219 | E21: 0.285 | F21: =C21*D21/3600 -> 232.26167 | G21: =F21/($D$4*(1-E21)*$D$5) -> 9.5541615 | H21: =ROUND(G21*1.01,0) -> 10 | I21: =H21-G21 -> 0.44583848 | J21: =H21/G21 -> 1.0466643 | K21: =IF(J21<0.95,"Understaffed",IF(J21>1.15,"Overstaffed","Balanced")) -> Balanced
A22: Takealot Care | B22: Wk 29 | C22: 3533 | D22: 252 | E22: 0.375 | F22: =C22*D22/3600 -> 247.31 | G22: =F22/($D$4*(1-E22)*$D$5) -> 11.638118 | H22: =ROUND(G22*1.023,0) -> 12 | I22: =H22-G22 -> 0.36188235 | J22: =H22/G22 -> 1.0310946 | K22: =IF(J22<0.95,"Understaffed",IF(J22>1.15,"Overstaffed","Balanced")) -> Balanced
A23: Takealot Care | B23: Wk 30 | C23: 4494 | D23: 320 | E23: 0.24 | F23: =C23*D23/3600 -> 399.46667 | G23: =F23/($D$4*(1-E23)*$D$5) -> 15.459236 | H23: =ROUND(G23*0.944,0) -> 15 | I23: =H23-G23 -> -0.45923633 | J23: =H23/G23 -> 0.97029372 | K23: =IF(J23<0.95,"Understaffed",IF(J23>1.15,"Overstaffed","Balanced")) -> Balanced
A24: Telkom Tech Support | B24: Wk 27 | C24: 3797 | D24: 259 | E24: 0.331 | F24: =C24*D24/3600 -> 273.17306 | G24: =F24/($D$4*(1-E24)*$D$5) -> 12.009718 | H24: =ROUND(G24*0.867,0) -> 10 | I24: =H24-G24 -> -2.0097184 | J24: =H24/G24 -> 0.83265899 | K24: =IF(J24<0.95,"Understaffed",IF(J24>1.15,"Overstaffed","Balanced")) -> Understaffed
A25: Telkom Tech Support | B25: Wk 28 | C25: 4335 | D25: 211 | E25: 0.276 | F25: =C25*D25/3600 -> 254.07917 | G25: =F25/($D$4*(1-E25)*$D$5) -> 10.321708 | H25: =ROUND(G25*1.046,0) -> 11 | I25: =H25-G25 -> 0.6782919 | J25: =H25/G25 -> 1.0657151 | K25: =IF(J25<0.95,"Understaffed",IF(J25>1.15,"Overstaffed","Balanced")) -> Balanced
A26: Telkom Tech Support | B26: Wk 29 | C26: 3412 | D26: 274 | E26: 0.267 | F26: =C26*D26/3600 -> 259.69111 | G26: =F26/($D$4*(1-E26)*$D$5) -> 10.420155 | H26: =ROUND(G26*1.039,0) -> 11 | I26: =H26-G26 -> 0.57984467 | J26: =H26/G26 -> 1.0556465 | K26: =IF(J26<0.95,"Understaffed",IF(J26>1.15,"Overstaffed","Balanced")) -> Balanced
A27: Telkom Tech Support | B27: Wk 30 | C27: 3657 | D27: 306 | E27: 0.246 | F27: =C27*D27/3600 -> 310.845 | G27: =F27/($D$4*(1-E27)*$D$5) -> 12.125332 | H27: =ROUND(G27*1.109,0) -> 13 | I27: =H27-G27 -> 0.87466844 | J27: =H27/G27 -> 1.0721356 | K27: =IF(J27<0.95,"Understaffed",IF(J27>1.15,"Overstaffed","Balanced")) -> Balanced
A28: Nedbank Debt Review | B28: Wk 27 | C28: 4344 | D28: 257 | E28: 0.331 | F28: =C28*D28/3600 -> 310.11333 | G28: =F28/($D$4*(1-E28)*$D$5) -> 13.633752 | H28: =ROUND(G28*0.877,0) -> 12 | I28: =H28-G28 -> -1.6337525 | J28: =H28/G28 -> 0.88016854 | K28: =IF(J28<0.95,"Understaffed",IF(J28>1.15,"Overstaffed","Balanced")) -> Understaffed
A29: Nedbank Debt Review | B29: Wk 28 | C29: 4155 | D29: 315 | E29: 0.261 | F29: =C29*D29/3600 -> 363.5625 | G29: =F29/($D$4*(1-E29)*$D$5) -> 14.469573 | H29: =ROUND(G29*0.994,0) -> 14 | I29: =H29-G29 -> -0.46957335 | J29: =H29/G29 -> 0.96754753 | K29: =IF(J29<0.95,"Understaffed",IF(J29>1.15,"Overstaffed","Balanced")) -> Balanced
A30: Nedbank Debt Review | B30: Wk 29 | C30: 4534 | D30: 299 | E30: 0.31 | F30: =C30*D30/3600 -> 376.57389 | G30: =F30/($D$4*(1-E30)*$D$5) -> 16.051743 | H30: =ROUND(G30*1.086,0) -> 17 | I30: =H30-G30 -> 0.94825708 | J30: =H30/G30 -> 1.059075 | K30: =IF(J30<0.95,"Understaffed",IF(J30>1.15,"Overstaffed","Balanced")) -> Balanced
A31: Nedbank Debt Review | B31: Wk 30 | C31: 3240 | D31: 332 | E31: 0.367 | F31: =C31*D31/3600 -> 298.8 | G31: =F31/($D$4*(1-E31)*$D$5) -> 13.883468 | H31: =ROUND(G31*0.982,0) -> 14 | I31: =H31-G31 -> 0.11653192 | J31: =H31/G31 -> 1.0083936 | K31: =IF(J31<0.95,"Understaffed",IF(J31>1.15,"Overstaffed","Balanced")) -> Balanced
A32: DStv Upsell | B32: Wk 27 | C32: 3191 | D32: 285 | E32: 0.363 | F32: =C32*D32/3600 -> 252.62083 | G32: =F32/($D$4*(1-E32)*$D$5) -> 11.664089 | H32: =ROUND(G32*0.973,0) -> 11 | I32: =H32-G32 -> -0.66408871 | J32: =H32/G32 -> 0.94306553 | K32: =IF(J32<0.95,"Understaffed",IF(J32>1.15,"Overstaffed","Balanced")) -> Understaffed
A33: DStv Upsell | B33: Wk 28 | C33: 2520 | D33: 327 | E33: 0.367 | F33: =C33*D33/3600 -> 228.9 | G33: =F33/($D$4*(1-E33)*$D$5) -> 10.635629 | H33: =ROUND(G33*1.054,0) -> 11 | I33: =H33-G33 -> 0.36437134 | J33: =H33/G33 -> 1.0342595 | K33: =IF(J33<0.95,"Understaffed",IF(J33>1.15,"Overstaffed","Balanced")) -> Balanced
A34: DStv Upsell | B34: Wk 29 | C34: 2757 | D34: 348 | E34: 0.318 | F34: =C34*D34/3600 -> 266.51 | G34: =F34/($D$4*(1-E34)*$D$5) -> 11.493445 | H34: =ROUND(G34*0.986,0) -> 11 | I34: =H34-G34 -> -0.49344489 | J34: =H34/G34 -> 0.95706728 | K34: =IF(J34<0.95,"Understaffed",IF(J34>1.15,"Overstaffed","Balanced")) -> Balanced
A35: DStv Upsell | B35: Wk 30 | C35: 3400 | D35: 231 | E35: 0.276 | F35: =C35*D35/3600 -> 218.16667 | G35: =F35/($D$4*(1-E35)*$D$5) -> 8.8627993 | H35: =ROUND(G35*1.073,0) -> 10 | I35: =H35-G35 -> 1.1372007 | J35: =H35/G35 -> 1.1283117 | K35: =IF(J35<0.95,"Understaffed",IF(J35>1.15,"Overstaffed","Balanced")) -> Balanced
A36: Discovery Lead Gen | B36: Wk 27 | C36: 3815 | D36: 279 | E36: 0.33 | F36: =C36*D36/3600 -> 295.6625 | G36: =F36/($D$4*(1-E36)*$D$5) -> 12.979039 | H36: =ROUND(G36*1.029,0) -> 13 | I36: =H36-G36 -> 0.02096137 | J36: =H36/G36 -> 1.001615 | K36: =IF(J36<0.95,"Understaffed",IF(J36>1.15,"Overstaffed","Balanced")) -> Balanced
A37: Discovery Lead Gen | B37: Wk 28 | C37: 4539 | D37: 270 | E37: 0.379 | F37: =C37*D37/3600 -> 340.425 | G37: =F37/($D$4*(1-E37)*$D$5) -> 16.123188 | H37: =ROUND(G37*0.981,0) -> 16 | I37: =H37-G37 -> -0.12318841 | J37: =H37/G37 -> 0.99235955 | K37: =IF(J37<0.95,"Understaffed",IF(J37>1.15,"Overstaffed","Balanced")) -> Balanced
A38: Discovery Lead Gen | B38: Wk 29 | C38: 3665 | D38: 221 | E38: 0.322 | F38: =C38*D38/3600 -> 224.99028 | G38: =F38/($D$4*(1-E38)*$D$5) -> 9.7601196 | H38: =ROUND(G38*1.07,0) -> 10 | I38: =H38-G38 -> 0.23988037 | J38: =H38/G38 -> 1.0245776 | K38: =IF(J38<0.95,"Understaffed",IF(J38>1.15,"Overstaffed","Balanced")) -> Balanced
A39: Discovery Lead Gen | B39: Wk 30 | C39: 3571 | D39: 295 | E39: 0.379 | F39: =C39*D39/3600 -> 292.62361 | G39: =F39/($D$4*(1-E39)*$D$5) -> 13.859222 | H39: =ROUND(G39*0.934,0) -> 13 | I39: =H39-G39 -> -0.8592219 | J39: =H39/G39 -> 0.9380036 | K39: =IF(J39<0.95,"Understaffed",IF(J39>1.15,"Overstaffed","Balanced")) -> Understaffed
A40: Cell C Winback | B40: Wk 27 | C40: 4302 | D40: 292 | E40: 0.276 | F40: =C40*D40/3600 -> 348.94 | G40: =F40/($D$4*(1-E40)*$D$5) -> 14.175333 | H40: =ROUND(G40*0.999,0) -> 14 | I40: =H40-G40 -> -0.17533312 | J40: =H40/G40 -> 0.98763111 | K40: =IF(J40<0.95,"Understaffed",IF(J40>1.15,"Overstaffed","Balanced")) -> Balanced
A41: Cell C Winback | B41: Wk 28 | C41: 3226 | D41: 249 | E41: 0.243 | F41: =C41*D41/3600 -> 223.13167 | G41: =F41/($D$4*(1-E41)*$D$5) -> 8.6693475 | H41: =ROUND(G41*1.027,0) -> 9 | I41: =H41-G41 -> 0.33065247 | J41: =H41/G41 -> 1.0381404 | K41: =IF(J41<0.95,"Understaffed",IF(J41>1.15,"Overstaffed","Balanced")) -> Balanced
A42: Cell C Winback | B42: Wk 29 | C42: 3341 | D42: 275 | E42: 0.332 | F42: =C42*D42/3600 -> 255.21528 | G42: =F42/($D$4*(1-E42)*$D$5) -> 11.237024 | H42: =ROUND(G42*1.016,0) -> 11 | I42: =H42-G42 -> -0.2370235 | J42: =H42/G42 -> 0.97890691 | K42: =IF(J42<0.95,"Understaffed",IF(J42>1.15,"Overstaffed","Balanced")) -> Balanced
...
