Workbook

Sheet Employee Master
A1: HR Employee Master Database
A2: Headcount, tenure and attrition source data — analytics on the next tab
A4: Emp ID | B4: Full Name | C4: Department | D4: Job Title | E4: Gender | F4: Location | G4: Hire Date | H4: Status | I4: Exit Date | J4: Tenure (yrs) | K4: Annual Salary
A5: EMP2001 | B5: Naledi Molefe | C5: Operations | D5: Agent | E5: M | F5: Johannesburg | G5: 44281 | H5: Active | J5: =(TODAY()-G5)/365.25 -> 5.3689254 | K5: 29000
A6: EMP2002 | B6: Kagiso Khumalo | C6: Customer Care | D6: CSR | E6: F | F6: Cape Town | G6: 45685 | H6: Active | J6: =(TODAY()-G6)/365.25 -> 1.5249829 | K6: 19500
A7: EMP2003 | B7: Zanele Mahlangu | C7: Sales | D7: Sales Rep | E7: M | F7: Durban | G7: 45881 | H7: Active | J7: =(TODAY()-G7)/365.25 -> 0.98836413 | K7: 19500
A8: EMP2004 | B8: Tumelo Sithole | C8: IT Support | D8: Technician | E8: F | F8: Pretoria | G8: 43852 | H8: Resigned | I8: 44724 | J8: =(I8-G8)/365.25 -> 2.3874059 | K8: 22000
A9: EMP2005 | B9: Ayanda Ndlovu | C9: Admin | D9: Coordinator | E9: M | F9: Johannesburg | G9: 45713 | H9: Active | J9: =(TODAY()-G9)/365.25 -> 1.4483231 | K9: 40000
A10: EMP2006 | B10: Bongani Mabaso | C10: Quality | D10: QA Analyst | E10: F | F10: Cape Town | G10: 44892 | H10: Active | J10: =(TODAY()-G10)/365.25 -> 3.6960986 | K10: 13000
A11: EMP2007 | B11: Nomvula Zulu | C11: HR | D11: HR Officer | E11: M | F11: Durban | G11: 43591 | H11: Active | J11: =(TODAY()-G11)/365.25 -> 7.2580424 | K11: 22000
A12: EMP2008 | B12: Kabelo Ngcobo | C12: Finance | D12: Accountant | E12: F | F12: Pretoria | G12: 43516 | H12: Active | J12: =(TODAY()-G12)/365.25 -> 7.4633812 | K12: 25000
A13: EMP2009 | B13: Refilwe Radebe | C13: Operations | D13: Agent | E13: M | F13: Johannesburg | G13: 44851 | H13: Resigned | I13: 46231 | J13: =(I13-G13)/365.25 -> 3.7782341 | K13: 19500
A14: EMP2010 | B14: Mpho Mthembu | C14: Customer Care | D14: CSR | E14: F | F14: Cape Town | G14: 44219 | H14: Active | J14: =(TODAY()-G14)/365.25 -> 5.5386721 | K14: 40000
A15: EMP2011 | B15: Lindiwe Tshabalala | C15: Sales | D15: Sales Rep | E15: M | F15: Durban | G15: 45922 | H15: Active | J15: =(TODAY()-G15)/365.25 -> 0.87611225 | K15: 19500
A16: EMP2012 | B16: Sibusiso Maseko | C16: IT Support | D16: Technician | E16: F | F16: Pretoria | G16: 44380 | H16: Active | J16: =(TODAY()-G16)/365.25 -> 5.0978782 | K16: 25000
A17: EMP2013 | B17: Palesa Cele | C17: Admin | D17: Coordinator | E17: M | F17: Johannesburg | G17: 45099 | H17: Active | J17: =(TODAY()-G17)/365.25 -> 3.1293634 | K17: 22000
A18: EMP2014 | B18: Katlego Buthelezi | C18: Quality | D18: QA Analyst | E18: F | F18: Cape Town | G18: 45068 | H18: Active | J18: =(TODAY()-G18)/365.25 -> 3.2142368 | K18: 29000
A19: EMP2015 | B19: Nonhlanhla Motaung | C19: HR | D19: HR Officer | E19: M | F19: Durban | G19: 45430 | H19: Resigned | I19: 46186 | J19: =(I19-G19)/365.25 -> 2.0698152 | K19: 17000
A20: EMP2016 | B20: Themba Sibiya | C20: Finance | D20: Accountant | E20: F | F20: Pretoria | G20: 45209 | H20: Active | J20: =(TODAY()-G20)/365.25 -> 2.8281999 | K20: 13000
A21: EMP2017 | B21: Dineo Naidoo | C21: Operations | D21: Agent | E21: M | F21: Johannesburg | G21: 44323 | H21: Active | J21: =(TODAY()-G21)/365.25 -> 5.2539357 | K21: 25000
A22: EMP2018 | B22: Musa Mokoena | C22: Customer Care | D22: CSR | E22: F | F22: Cape Town | G22: 44788 | H22: Active | J22: =(TODAY()-G22)/365.25 -> 3.980835 | K22: 40000
A23: EMP2019 | B23: Precious Nkosi | C23: Sales | D23: Sales Rep | E23: M | F23: Durban | G23: 44901 | H23: Active | J23: =(TODAY()-G23)/365.25 -> 3.6714579 | K23: 22000
A24: EMP2020 | B24: Andile Dlamini | C24: IT Support | D24: Technician | E24: F | F24: Pretoria | G24: 45251 | H24: Active | J24: =(TODAY()-G24)/365.25 -> 2.7132101 | K24: 15000
A25: EMP2021 | B25: Boitumelo Molefe | C25: Admin | D25: Coordinator | E25: M | F25: Johannesburg | G25: 45769 | H25: Active | J25: =(TODAY()-G25)/365.25 -> 1.2950034 | K25: 19500
A26: EMP2022 | B26: Lwazi Khumalo | C26: Quality | D26: QA Analyst | E26: F | F26: Cape Town | G26: 43832 | H26: Active | J26: =(TODAY()-G26)/365.25 -> 6.5982204 | K26: 34000
A27: EMP2023 | B27: Zodwa Mahlangu | C27: HR | D27: HR Officer | E27: M | F27: Durban | G27: 44972 | H27: Active | J27: =(TODAY()-G27)/365.25 -> 3.4770705 | K27: 19500
A28: EMP2024 | B28: Tshepo Sithole | C28: Finance | D28: Accountant | E28: F | F28: Pretoria | G28: 45639 | H28: Active | J28: =(TODAY()-G28)/365.25 -> 1.650924 | K28: 19500
A29: EMP2025 | B29: Amahle Ndlovu | C29: Operations | D29: Agent | E29: M | F29: Johannesburg | G29: 44158 | H29: Resigned | I29: 44576 | J29: =(I29-G29)/365.25 -> 1.1444216 | K29: 29000
A30: EMP2026 | B30: Sanele Mabaso | C30: Customer Care | D30: CSR | E30: F | F30: Cape Town | G30: 43916 | H30: Active | J30: =(TODAY()-G30)/365.25 -> 6.3682409 | K30: 40000
A31: EMP2027 | B31: Nokuthula Zulu | C31: Sales | D31: Sales Rep | E31: M | F31: Durban | G31: 44579 | H31: Active | J31: =(TODAY()-G31)/365.25 -> 4.5530459 | K31: 15000
A32: EMP2028 | B32: Gift Ngcobo | C32: IT Support | D32: Technician | E32: F | F32: Pretoria | G32: 44646 | H32: Active | J32: =(TODAY()-G32)/365.25 -> 4.3696099 | K32: 40000
A33: EMP2029 | B33: Portia Radebe | C33: Admin | D33: Coordinator | E33: M | F33: Johannesburg | G33: 45210 | H33: Active | J33: =(TODAY()-G33)/365.25 -> 2.825462 | K33: 34000
A34: EMP2030 | B34: Siyabonga Mthembu | C34: Quality | D34: QA Analyst | E34: F | F34: Cape Town | G34: 45277 | H34: Active | J34: =(TODAY()-G34)/365.25 -> 2.642026 | K34: 40000
A35: EMP2031 | B35: Lesego Tshabalala | C35: HR | D35: HR Officer | E35: M | F35: Durban | G35: 44644 | H35: Active | J35: =(TODAY()-G35)/365.25 -> 4.3750856 | K35: 34000
A36: EMP2032 | B36: Mandla Maseko | C36: Finance | D36: Accountant | E36: F | F36: Pretoria | G36: 44313 | H36: Active | J36: =(TODAY()-G36)/365.25 -> 5.2813142 | K36: 40000
A37: EMP2033 | B37: Nosipho Cele | C37: Operations | D37: Agent | E37: M | F37: Johannesburg | G37: 44873 | H37: Active | J37: =(TODAY()-G37)/365.25 -> 3.7481177 | K37: 15000
A38: EMP2034 | B38: Neo Buthelezi | C38: Customer Care | D38: CSR | E38: F | F38: Cape Town | G38: 45420 | H38: Active | J38: =(TODAY()-G38)/365.25 -> 2.2505133 | K38: 25000
A39: EMP2035 | B39: Zinhle Motaung | C39: Sales | D39: Sales Rep | E39: M | F39: Durban | G39: 44962 | H39: Resigned | I39: 45946 | J39: =(I39-G39)/365.25 -> 2.6940452 | K39: 17000
A40: EMP2036 | B40: Vusi Sibiya | C40: IT Support | D40: Technician | E40: F | F40: Pretoria | G40: 45385 | H40: Active | J40: =(TODAY()-G40)/365.25 -> 2.3463381 | K40: 25000
A41: EMP2037 | B41: Ntombi Naidoo | C41: Admin | D41: Coordinator | E41: M | F41: Johannesburg | G41: 45152 | H41: Resigned | I41: 46212 | J41: =(I41-G41)/365.25 -> 2.9021218 | K41: 29000
...

Sheet Analytics
A1: HR Analytics & Attrition Dashboard
A2: All metrics reference the Employee Master tab
A4: Total Headcount | B4: =COUNTA('Employee Master'!A5:A44) -> 40
A5: Active | B5: =COUNTIF('Employee Master'!H5:H44,"Active") -> 33
A6: Resigned | B6: =COUNTIF('Employee Master'!H5:H44,"Resigned") -> 7
A7: Attrition Rate | B7: =B6/B4 -> 0.175
A8: Avg Tenure (yrs) | B8: =AVERAGE('Employee Master'!J5:J44) -> 3.4778919
A9: Avg Salary | B9: =AVERAGE('Employee Master'!K5:K44) -> 25350
A10: % Female | B10: =COUNTIF('Employee Master'!E5:E44,"F")/B4 -> 0.5
A13: Department | B13: Headcount | C13: Resigned | D13: Avg Salary
A14: Operations | B14: =COUNTIF('Employee Master'!C5:C44,A14) -> 5 | C14: =COUNTIFS('Employee Master'!C5:C44,A14,'Employee Master'!H5:H44,"Resigned") -> 2 | D14: =AVERAGEIF('Employee Master'!C5:C44,A14,'Employee Master'!K5:K44) -> 23500
A15: Customer Care | B15: =COUNTIF('Employee Master'!C5:C44,A15) -> 5 | C15: =COUNTIFS('Employee Master'!C5:C44,A15,'Employee Master'!H5:H44,"Resigned") -> 0 | D15: =AVERAGEIF('Employee Master'!C5:C44,A15,'Employee Master'!K5:K44) -> 32900
A16: Sales | B16: =COUNTIF('Employee Master'!C5:C44,A16) -> 5 | C16: =COUNTIFS('Employee Master'!C5:C44,A16,'Employee Master'!H5:H44,"Resigned") -> 1 | D16: =AVERAGEIF('Employee Master'!C5:C44,A16,'Employee Master'!K5:K44) -> 18600
A17: IT Support | B17: =COUNTIF('Employee Master'!C5:C44,A17) -> 5 | C17: =COUNTIFS('Employee Master'!C5:C44,A17,'Employee Master'!H5:H44,"Resigned") -> 1 | D17: =AVERAGEIF('Employee Master'!C5:C44,A17,'Employee Master'!K5:K44) -> 25400
A18: Admin | B18: =COUNTIF('Employee Master'!C5:C44,A18) -> 5 | C18: =COUNTIFS('Employee Master'!C5:C44,A18,'Employee Master'!H5:H44,"Resigned") -> 1 | D18: =AVERAGEIF('Employee Master'!C5:C44,A18,'Employee Master'!K5:K44) -> 28900
A19: Quality | B19: =COUNTIF('Employee Master'!C5:C44,A19) -> 5 | C19: =COUNTIFS('Employee Master'!C5:C44,A19,'Employee Master'!H5:H44,"Resigned") -> 1 | D19: =AVERAGEIF('Employee Master'!C5:C44,A19,'Employee Master'!K5:K44) -> 25800
A20: HR | B20: =COUNTIF('Employee Master'!C5:C44,A20) -> 5 | C20: =COUNTIFS('Employee Master'!C5:C44,A20,'Employee Master'!H5:H44,"Resigned") -> 1 | D20: =AVERAGEIF('Employee Master'!C5:C44,A20,'Employee Master'!K5:K44) -> 24300
A21: Finance | B21: =COUNTIF('Employee Master'!C5:C44,A21) -> 5 | C21: =COUNTIFS('Employee Master'!C5:C44,A21,'Employee Master'!H5:H44,"Resigned") -> 0 | D21: =AVERAGEIF('Employee Master'!C5:C44,A21,'Employee Master'!K5:K44) -> 23400
